<?xml version = "1.0"?>
<robot name="agv" xmlns:xacro="http://ros.org/wiki/xacro">
	<link name="base_footprint">
		<visual>
			 <origin xyz="0 0 0" rpy="0 0 0"/>
			 <geometry>
				 <box size= "0.01 0.01 0.01" />
			 </geometry>
			 <material name="light_black"/>
		 </visual>
		
		 <inertial>
			 <origin xyz="0 0 0" rpy="0 0 0"/>
			 <mass value="0.01"/>
			 <inertia ixx="0.01" ixy="0.0" ixz="0.0"
					  iyy="0.01" iyz="0.0"
					  izz="0.01" />
		 </inertial>
	</link>
	<joint name="base_joint" type="fixed">
		<parent link="base_footprint"/>
		<child link="base_link" />
		<origin xyz="0 0 0" rpy="0 0 0"/>
	</joint>
	
	 <link name="base_link">
		 <visual>
			 <origin xyz="0 0 0.1" rpy="0 0 0"/>
			 <geometry>
				 <box size= "0.4 0.2 0.1" />
			 </geometry>
			 <material name="light_black"/>
		 </visual>
		 <collision>
			 <origin xyz="0 0 0.1" rpy="0 0 0"/>
			 <geometry>
				 <box size= "0.4 0.2 0.1" />
			 </geometry>
		 </collision>
		 <inertial>
			 <origin xyz="0 0 0.1" rpy="0 0 0"/>
			 <mass value="10"/>
			 <inertia ixx="0.01" ixy="0.0" ixz="0.0"
					  iyy="0.01" iyz="0.0"
					  izz="0.01" />
		 </inertial>
	</link>
	
	<link name="caster_ball_1">
		 <visual>
			 <origin xyz="0 0 0" rpy="0 0 0"/>
			 <geometry>
				 <sphere radius = "0.05"/>
			 </geometry>
			 <material name="light_black"/>
		 </visual>
		 <collision>
			 <origin xyz="0 0 0" rpy="0 0 0"/>
			 <geometry>
				 <sphere radius = "0.05"/>
			 </geometry>
		 </collision>
		 <inertial>
			 <origin xyz="0 0 0" rpy="0 0 0"/>
			 <mass value="1"/>
			 <inertia ixx="0.01" ixy="0.0" ixz="0.0"
					  iyy="0.01" iyz="0.0"
					  izz="0.01" />
		 </inertial>
		
	</link>
	
	<joint name="ball_joint_1" type="fixed">
		<parent link="base_link"/>
		<child link="caster_ball_1" />
		<origin xyz="-0.15 0 0.05"  rpy="0 0 0"/>
		<axis xyz="0 1 1"/>
	</joint>

	<link name="caster_ball_2">
		 <visual>
			 <origin xyz="0 0 0" rpy="0 0 0"/>
			 <geometry>
				 <sphere radius = "0.045"/>
			 </geometry>
			 <material name="light_black"/>
		 </visual>
		 <collision>
			 <origin xyz="0 0 0" rpy="0 0 0"/>
			 <geometry>
				 <sphere radius = "0.045"/>
			 </geometry>
		 </collision>
		 <inertial>
			 <origin xyz="0 0 0" rpy="0 0 0"/>
			 <mass value="1"/>
			 <inertia ixx="0.01" ixy="0.0" ixz="0.0"
					  iyy="0.01" iyz="0.0"
					  izz="0.01" />
		 </inertial>
	</link>
	
	<joint name="ball_joint_2" type="fixed">
		<parent link="base_link"/>
		<child link="caster_ball_2" />
		<origin xyz="0.15 0 0.05"  rpy="0 0 0"/>
		<axis xyz="0 1 1"/>
	</joint>
	
	<link name="left_wheel">
		 <visual>
			 <origin xyz="0 0 0" rpy="0 0 0"/>
			 <geometry>
				 <cylinder radius = "0.1" length ="0.05"/>
			 </geometry>
			 <material name="light_black"/>
		 </visual>	
		 <collision>
			 <origin xyz="0 0 0" rpy="0 0 0"/>
			 <geometry>
				  <cylinder radius = "0.1" length ="0.00001"/>
			 </geometry>
		 </collision>
		 <inertial>
			 <origin xyz="0 0 0" rpy="0 0 0"/>
			 <mass value="1"/>
			 <inertia ixx="0.01" ixy="0.0" ixz="0.0"
					  iyy="0.01" iyz="0.0"
					  izz="0.01" />
		 </inertial>
	</link>
	<joint name="left_wheel_joint" type="continuous">
		<parent link="base_link"/>
		<child link="left_wheel" />
		<origin xyz="0 0.13 0.1" rpy="0 1.5707 1.5707"/>
		<axis xyz="0 0 1"/>
	</joint>
	
	<link name="right_wheel">
		 <visual>
			 <origin xyz="0 0 0" rpy="0 0 0"/>
			 <geometry>
				 <cylinder radius = "0.1" length ="0.05"/>
			 </geometry>
			 <material name="light_black"/>
		 </visual>
		
		 <collision>
			 <origin xyz="0 0 0" rpy="0 0 0"/>
			 <geometry>
				  <cylinder radius = "0.1" length ="0.00001"/>
			 </geometry>
		 </collision>
		 <inertial>
			 <origin xyz="0 0 0" rpy="0 0 0"/>
			 <mass value="1"/>
			 <inertia ixx="0.01" ixy="0.0" ixz="0.0"
					  iyy="0.01" iyz="0.0"
					  izz="0.01" />
		 </inertial>
	</link>
	<joint name="right_wheel_joint" type="continuous">
		<parent link="base_link"/>
		<child link="right_wheel" />
		<origin xyz="0 -0.13 0.1" rpy="0 1.5707 1.5707"/>
		<axis xyz="0 0 1"/>
	</joint>
	
	
	<link name = "laser_sensor_link">
		<visual>
			 <origin xyz="0 0 -0.03" rpy="0 0 0"/>
			 <geometry>
				 <mesh filename = "package://agv_description/meshes/hokuyo.dae" />
			 </geometry>
			 <material name="light_black"/>
		 </visual>
		 <collision>
			 <origin xyz="0 0 -0.03" rpy="0 0 0"/>
			 <geometry>
				  <box size= "0.01 0.01 0.01" />
			 </geometry>
		 </collision>
		 <inertial>
			 <origin xyz="0 0 0" rpy="0 0 0"/>
			 <mass value="0.5"/>
			 <inertia ixx="0.01" ixy="0.0" ixz="0.0"
					  iyy="0.01" iyz="0.0"
					  izz="0.01" />
		 </inertial>
	</link>
	<joint name="hokuyo_joint" type="fixed">
		<parent link="base_link"/>
		<child link="laser_sensor_link" />
		<origin xyz="0.15 0 0.22" rpy="0 0 0"/>
	</joint>
	
	<gazebo reference = "laser_sensor_link">
		<sensor name = "laser" type = "ray" >
			<pose>0.15 0 0 0 0 0 </pose>
			<always_on>1</always_on>
			<update_rate>30</update_rate>
			<visualize>true</visualize>
		t	<ray>
				<scan>
					<horizontal>
						<sample>240</sample>
						<resolution>2</resolution>
						<min_angle>-2.26889</min_angle>
						<max_angle> 2.26899</max_angle>
					</horizontal>
				</scan>
				<range>
					<min>0.08</min>
					<max> 10 </max>
					<resolution>0.01</resolution>
				</range>
				<noise>
					<type>gaussian</type>
					<mean>0.0</mean>
					<stddev>0.0</stddev>
				</noise>
			</ray>
			<plugin name = "laser" filename = "libgazebo_ros_laser.so">
				<topicName>sensor_msgs/LaserScan</topicName>
				<frameName>laser_sensor_link</frameName>
			</plugin>
		</sensor>
	</gazebo>
	
	<gazebo>
		<plugin name="differential_drive_controller" filename="libgazebo_ros_diff_drive.so">
			<commandTopic>cmd_vel</commandTopic>
			<odometryTopic>odom</odometryTopic>
			<odometryFrame>odom</odometryFrame>
			<robotBaseFrame>base_footprint</robotBaseFrame> 
			<publishWheelTF>true</publishWheelTF> 
			<publishWheelJointState>true</publishWheelJointState>
			<wheelSeparation>0.13</wheelSeparation> 
			<wheelDiameter>0.1</wheelDiameter>
			<wheelAcceleration>0.5</wheelAcceleration>
			<wheelTorque>500</wheelTorque>
			<updateRate>100</updateRate>
			<alwaysOn>true</alwaysOn>
			<rosDebugLevel>0</rosDebugLevel> 
			<leftJoint>right_wheel_joint</leftJoint>
			<rightJoint>left_wheel_joint</rightJoint>
			<odometrySource>world</odometrySource>
			<publishTf>1</publishTf>
			<legacyMode>true</legacyMode>
		</plugin>
	</gazebo>	
	
</robot>

	
	
	
	
	
	
	
	
	
	
	
	
	
	
	
	
	
	
	
	
	
	
	
	
	
	
	
	
	
	
	
	
	
	
	
	
	
	
	
	
	
	
	
	
	
	
	
	
	
	
	