<?xml version = "1.0"?>
<robot name="agv" xmlns:xacro="http://ros.org/wiki/xacro">
	
	<link name="base_footprint"/>
	<joint name="base_joint" type="fixed">
		<parent link="base_footprint"/>
		<child link="base_link" />
		<origin xyz="0 0 0.1" rpy="0 0 0"/>
	</joint>
	
	 <link name="base_link">
		 <visual>
			 <origin xyz="0 0 0.1" rpy="0 0 0"/>
			 <geometry>
				 <box size= "0.4 0.2 0.1" />
			 </geometry>
			 <material name="light_black"/>
		 </visual>
		 <collision>
			 <origin xyz="0 0 0.1" rpy="0 0 0"/>
			 <geometry>
				 <box size= "0.4 0.2 0.1" />
			 </geometry>
		 </collision>
		 <inertial>
			 <origin xyz="0 0 0.1" rpy="0 0 0"/>
			 <mass value="10"/>
			 <inertia ixx="0.01" ixy="0.0" ixz="0.0"
					  iyy="0.01" iyz="0.0"
					  izz="0.01" />
		 </inertial>
	</link>
	
	<link name="caster_ball_1">
		 <visual>
			 <origin xyz="0 0 0" rpy="0 0 0"/>
			 <geometry>
				 <sphere radius = "0.05"/>
			 </geometry>
			 <material name="light_black"/>
		 </visual>
		 <collision>
			 <origin xyz="0 0 0" rpy="0 0 0"/>
			 <geometry>
				 <sphere radius = "0.05"/>
			 </geometry>
		 </collision>
		 <inertial>
			 <origin xyz="0 0 0" rpy="0 0 0"/>
			 <mass value="1"/>
			 <inertia ixx="0.01" ixy="0.0" ixz="0.0"
					  iyy="0.01" iyz="0.0"
					  izz="0.01" />
		 </inertial>
		
	</link>
	
	<joint name="ball_joint_1" type="fixed">
		<parent link="base_link"/>
		<child link="caster_ball_1" />
		<origin xyz="-0.15 0 0.05"  rpy="0 0 0"/>
		<axis xyz="0 1 1"/>
	</joint>

	<link name="caster_ball_2">
		 <visual>
			 <origin xyz="0 0 0" rpy="0 0 0"/>
			 <geometry>
				 <sphere radius = "0.045"/>
			 </geometry>
			 <material name="light_black"/>
		 </visual>
		 <collision>
			 <origin xyz="0 0 0" rpy="0 0 0"/>
			 <geometry>
				 <sphere radius = "0.045"/>
			 </geometry>
		 </collision>
		 <inertial>
			 <origin xyz="0 0 0" rpy="0 0 0"/>
			 <mass value="1"/>
			 <inertia ixx="0.01" ixy="0.0" ixz="0.0"
					  iyy="0.01" iyz="0.0"
					  izz="0.01" />
		 </inertial>
	</link>
	
	<joint name="ball_joint_2" type="fixed">
		<parent link="base_link"/>
		<child link="caster_ball_2" />
		<origin xyz="0.15 0 0.05"  rpy="0 0 0"/>
		<axis xyz="0 1 1"/>
	</joint>
	
	<link name="left_wheel">
		 <visual>
			 <origin xyz="0 0 0" rpy="0 0 0"/>
			 <geometry>
				 <cylinder radius = "0.1" length ="0.05"/>
			 </geometry>
			 <material name="light_black"/>
		 </visual>	
		 <collision>
			 <origin xyz="0 0 0" rpy="0 0 0"/>
			 <geometry>
				  <cylinder radius = "0.1" length ="0.00001"/>
			 </geometry>
		 </collision>
		 <inertial>
			 <origin xyz="0 0 0" rpy="0 0 0"/>
			 <mass value="1"/>
			 <inertia ixx="0.01" ixy="0.0" ixz="0.0"
					  iyy="0.01" iyz="0.0"
					  izz="0.01" />
		 </inertial>
	</link>
	<joint name="left_wheel_joint" type="continuous">
		<parent link="base_link"/>
		<child link="left_wheel" />
		<origin xyz="0 0.13 0.1" rpy="0 1.5707 1.5707"/>
		<axis xyz="0 0 1"/>
	</joint>
	
	<link name="right_wheel">
		 <visual>
			 <origin xyz="0 0 0" rpy="0 0 0"/>
			 <geometry>
				 <cylinder radius = "0.1" length ="0.05"/>
			 </geometry>
			 <material name="light_black"/>
		 </visual>
		
		 <collision>
			 <origin xyz="0 0 0" rpy="0 0 0"/>
			 <geometry>
				  <cylinder radius = "0.1" length ="0.00001"/>
			 </geometry>
		 </collision>
		 <inertial>
			 <origin xyz="0 0 0" rpy="0 0 0"/>
			 <mass value="1"/>
			 <inertia ixx="0.01" ixy="0.0" ixz="0.0"
					  iyy="0.01" iyz="0.0"
					  izz="0.01" />
		 </inertial>
	</link>
	<joint name="right_wheel_joint" type="continuous">
		<parent link="base_link"/>
		<child link="right_wheel" />
		<origin xyz="0 -0.13 0.1" rpy="0 1.5707 1.5707"/>
		<axis xyz="0 0 1"/>
	</joint>
	
	
	<link name = "laser_sensor_link">
		<visual>
			 <origin xyz="0 0 -0.03" rpy="0 0 0"/>
			 <geometry>
				 <mesh filename = "package://agv_description/meshes/hokuyo.dae" />
			 </geometry>
			 <material name="light_black"/>
		 </visual>
		 <collision>
			 <origin xyz="0 0 -0.03" rpy="0 0 0"/>
			 <geometry>
				  <box size= "0.01 0.01 0.01" />
			 </geometry>
		 </collision>
		 <inertial>
			 <origin xyz="0 0 0" rpy="0 0 0"/>
			 <mass value="0.5"/>
			 <inertia ixx="0.01" ixy="0.0" ixz="0.0"
					  iyy="0.01" iyz="0.0"
					  izz="0.01" />
		 </inertial>
	</link>
	<joint name="hokuyo_joint" type="fixed">
		<parent link="base_link"/>
		<child link="laser_sensor_link" />
		<origin xyz="0.15 0 0.22" rpy="0 0 0"/>
	</joint>

</robot>

	
	
	
	
	
	
	
	
	
	
	
	
	
	
	
	
	
	
	
	
	
	
	
	
	
	
	
	
	
	
	
	
	
	
	
	
	
	
	
	
	
	
	
	
	
	
	
	
	
	
	